<?xml version="1.0"?>
<robot name="rover_arm">
  <material name="mat_silver">
    <color rgba="0.8 0.8 0.8 1"/>
  </material>

  <link name="world" />
  <link name="base_link">
    <visual>
      <origin xyz="0 0 0.08" rpy="0 0 0"/>
      <geometry>
        <mesh filename="../meshes/base_link.stl" scale="1 1 1"/>
      </geometry>
      <material name="mat_silver"/>
    </visual>
    <collision>
      <origin xyz="0 0 0.1" rpy="0 0 0" />
      <geometry>
        <box size="0.16 0.16 0.17" />
      </geometry>
    </collision>
    <inertial>
      <mass value="100"/>
      <inertia ixx="0.4542" ixy="0.0" ixz="0.0" iyy="0.4542" iyz="0.0" izz="0.4267"/>
    </inertial>
  </link>

  <link name="link1">
    <visual>
      <origin xyz="0 0 -0.1" rpy="0 0 0 " />
      <geometry>
         <mesh filename="../meshes/link_1.stl" scale="1 1 1"/>
      </geometry>
      <material name="mat_silver" />
    </visual>
    <collision>
      <origin xyz="0 0.023 0.105" rpy="0 0 0" />
      <geometry>
       <box size="0.1 0.05 0.155" />
      </geometry>
    </collision>
    <inertial>
      <mass value="1"/>
      <inertia ixx="0.0022" ixy="0.0" ixz="0.0" iyy="0.0028" iyz="0.0" izz="0.0001"/>
    </inertial>
  </link>

  <link name="link2">
    <visual>
      <origin xyz="0 0 -0.22" rpy="0 0 0" />
      <geometry>
        <mesh filename="../meshes/link_2.stl" scale="1 1 1"/>
     </geometry>
     <material name="mat_silver" />
    </visual>
    <collision>
      <origin xyz="0 -0.03 0.155" rpy="0 0 0" />
      <geometry>
       <box size="0.1 0.04 0.45" />
     </geometry>
    </collision>
    <inertial>
     <mass value="1"/>
     <inertia ixx="0.017" ixy="0.0" ixz="0.0" iyy="0.0177" iyz="0.0" izz="0.001"/>
   </inertial>
  </link>
 <link name="link3">
    <visual>
        <origin xyz="0 0 -0.565" rpy="0 0 0" />
        <geometry>
          <mesh filename="../meshes/link_3.stl" scale="1 1 1"/>
       </geometry>
       <material name="mat_silver" />
      </visual>
    <collision>
      <origin xyz="0.01 0.036 0.115" rpy="0 0 0" />
      <geometry>
        <box size="0.12 0.04 0.32" />
      </geometry>
    </collision>
    <inertial>
      <mass value="1"/>
      <inertia ixx="0.0087" ixy="0.0" ixz="0.0" iyy="0.0097" iyz="0.0" izz="0.0013"/>
    </inertial>
  </link>
  <link name="link4">

    <visual>
        <origin xyz="0 0 -0.8" rpy="0 0 0" />
        <geometry>
          <mesh filename="../meshes/link_4.stl" scale="1 1 1"/>
       </geometry>
       <material name="mat_silver" />
      </visual>
    <collision>
      <origin xyz="0.01 -0.022 0" rpy="0 0 0" />
      <geometry>
        <box size="0.1 0.06 0.08" />
      </geometry>
    </collision>
    <inertial>
      <mass value="1"/>
      <inertia ixx="0.0008" ixy="0.0" ixz="0.0" iyy="0.0014" iyz="0.0" izz="0.0011"/>
    </inertial>
  </link>
  <link name="link5">
    <visual>
        <origin xyz="0 0 -0.85" rpy="0 0 0" />
        <geometry>
          <mesh filename="../meshes/link_5.stl" scale="1 1 1"/>
       </geometry>
       <material name="mat_silver" />
      </visual>
    <collision>
      <origin xyz="0.01 -0.02 0.1" rpy="0 0 0" />
      <geometry>
        <box size="0.2 0.06 0.12" />
      </geometry>
    </collision>
    <inertial>
      <mass value="1"/>
      <inertia ixx="0.0015" ixy="0.0" ixz="0.0" iyy="0.0045" iyz="0.0" izz="0.0036"/>
    </inertial>
  </link>
  <link name="extender">
    <visual>
        <origin xyz="0.00193 0.133 0" rpy="0 0 -1.57" />
        <geometry>
          <box size="0.146 0.01 0.01"/>
      </geometry>
      <material name="mat_silver" />
      </visual>
      <visual>
        <origin xyz="0.0085 0.2125 0.0725" rpy="0 1.5707 0" />
        <geometry>
          <box size="0.146 0.007 0.01"/>
      </geometry>
      <material name="mat_silver" />
      </visual>
      <collision>
        <origin xyz="0.00193 0.133 0" rpy="0 0 -1.57" />
        <geometry>
          <box size="0.146 0.01 0.01"/>
      </geometry>
      </collision>
      <collision>
        <origin xyz="-0.173 0.213 0" rpy="0 0 0" />
        <geometry>
          <box size="0.363 0.007 0.01"/>
      </geometry>
      </collision>
      <inertial>
        <mass value="0.01"/>
        <inertia ixx="0.0015" ixy="0.0" ixz="0.0" iyy="0.0045" iyz="0.0" izz="0.0036"/>
      </inertial>

  </link>


  <link name="camera_link">
    <visual>
      <origin xyz="0.0085 0.213 0.146" rpy="0 0 0" />
      <geometry>
        <box size="0.04 0.034 0.043"/>
     </geometry>

    </visual>
    <collision>
      <origin xyz="-0.383 0.213 0.35" rpy="0 0 0" />
      <geometry>
        <box size="0.04 0.034 0.043"/>
     </geometry>
    </collision>
    <inertial>
      <mass value="0"/>
      <inertia ixx="0.0" ixy="0.0" ixz="0.0" iyy="0.0" iyz="0.0" izz="0.0"/>
    </inertial>
  </link>

 <joint name="extender_joint" type="fixed">
    <parent link="link4" />
    <child link="extender" />
    <origin xyz="0 0 0" rpy="0 0 0" />
  </joint>

  <joint name="camera_joint" type="fixed">
    <parent link="extender" />
    <child link="camera_link" />
    <origin xyz="0 0 0" rpy="0 0 0" />
  </joint>



  <joint name="base_joint" type="fixed">
    <parent link="world" />
    <child link="base_link" />
    <origin xyz="0 0 0" rpy="0 0 0" />
  </joint>


  <joint name="joint1" type="continuous">
    <parent link="base_link" />
    <child link="link1" />
    <origin xyz="0 0 0.18" rpy="0 0 0" />
   <axis xyz="0 0 1" />
  </joint>

  <joint name="joint2" type="revolute">
    <parent link="link1" />
    <child link="link2" />
    <origin xyz="0 0 0.12" rpy="0 0 0" />
    <axis xyz="0 1 0" />
    <limit lower="-1.5707" upper="1.5707" velocity="100" effort="100" />
  </joint>

  <joint name="joint3" type="revolute">
      <parent link="link2" />
      <child link="link3" />
      <origin xyz="0 0 0.345" rpy="0 0 0" />
      <axis xyz="0 1 0" />
      <limit lower="-1.5707" upper="1.5707" velocity="100" effort="100" />
  </joint>
  <joint name="joint4" type="revolute">
    <parent link="link3" />
    <child link="link4" />
    <origin xyz="0 0 0.24" rpy="0 0 0" />
    <axis xyz="0 1 0" />
    <limit lower="-1.5707" upper="1.5707" velocity="100" effort="100" />
</joint>
<joint name="joint5" type="revolute">
    <parent link="link4" />
    <child link="link5" />
    <origin xyz="0 0 0.05" rpy="0 0 0" />
    <axis xyz="0 0 1" />
    <limit lower="-1.5707" upper="1.5707" velocity="100" effort="100" />
</joint>



  <transmission name="tran1">
    <type>transmission_interface/SimpleTransmission</type>
    <joint name="joint1">
      <hardwareInterface>hardware_interface/EffortJointInterface</hardwareInterface>
    </joint>
    <actuator name="motor1">
      <hardwareInterface>hardware_interface/EffortJointInterface</hardwareInterface>
      <mechanicalReduction>1</mechanicalReduction>
    </actuator>
  </transmission>

  <transmission name="tran2">
    <type>transmission_interface/SimpleTransmission</type>
    <joint name="joint2">
      <hardwareInterface>hardware_interface/EffortJointInterface</hardwareInterface>
    </joint>
    <actuator name="motor2">
      <hardwareInterface>hardware_interface/EffortJointInterface</hardwareInterface>
      <mechanicalReduction>1</mechanicalReduction>
    </actuator>
  </transmission>

  <transmission name="tran3">
    <type>transmission_interface/SimpleTransmission</type>
    <joint name="joint3">
      <hardwareInterface>hardware_interface/EffortJointInterface</hardwareInterface>
    </joint>
    <actuator name="motor3">
      <hardwareInterface>hardware_interface/EffortJointInterface</hardwareInterface>
      <mechanicalReduction>1</mechanicalReduction>
    </actuator>
  </transmission>


  <transmission name="tran4">
    <type>transmission_interface/SimpleTransmission</type>
    <joint name="joint4">
      <hardwareInterface>hardware_interface/EffortJointInterface</hardwareInterface>
    </joint>
    <actuator name="motor4">
      <hardwareInterface>hardware_interface/EffortJointInterface</hardwareInterface>
      <mechanicalReduction>1</mechanicalReduction>
    </actuator>
  </transmission>
  <transmission name="tran5">
    <type>transmission_interface/SimpleTransmission</type>
    <joint name="joint5">
      <hardwareInterface>hardware_interface/EffortJointInterface</hardwareInterface>
    </joint>
    <actuator name="motor5">
      <hardwareInterface>hardware_interface/EffortJointInterface</hardwareInterface>
      <mechanicalReduction>1</mechanicalReduction>
    </actuator>
  </transmission>

  <gazebo reference="camera_link">
    <sensor type="camera" name="arm_camera">
      <update_rate>30.0</update_rate>
      <camera name="head">
        <horizontal_fov>1.3962634</horizontal_fov>
        <image>
          <width>800</width>
          <height>800</height>
          <format>R8G8B8</format>
        </image>
        <clip>
          <near>0.02</near>
          <far>300</far>
        </clip>
        <noise>
          <type>gaussian</type>
          <mean>0.0</mean>
          <stddev>0.007</stddev>
        </noise>
      </camera>
      <plugin name="camera_controller" filename="libgazebo_ros_camera.so">
        <alwaysOn>true</alwaysOn>
        <updateRate>0.0</updateRate>
        <cameraName>/arm_camera</cameraName>
        <imageTopicName>image_raw</imageTopicName>
        <cameraInfoTopicName>camera_info</cameraInfoTopicName>
        <frameName>camera_link</frameName>
        <hackBaseline>0.07</hackBaseline>
        <distortionK1>0.0</distortionK1>
        <distortionK2>0.0</distortionK2>
        <distortionK3>0.0</distortionK3>
        <distortionT1>0.0</distortionT1>
        <distortionT2>0.0</distortionT2>
      </plugin>
    </sensor>
  </gazebo>
  <gazebo>
    <plugin name="gazebo_ros_control" filename="libgazebo_ros_control.so">
      <robotNamespace>/</robotNamespace>
    </plugin>
  </gazebo>



</robot>
