<?xml version="1.0"?>
<robot name="rover_arm">
  <link name="world" />
  <link name="base_link">
    <visual>
      <origin xyz="0 0 0.08" rpy="0 0 0"/>
      <geometry>
        <mesh filename="../meshes/base_link.stl" scale="1 1 1"/>
      </geometry>
      <material name="mat_silver"/>
    </visual>
    <collision>
      <origin xyz="0 0 0.1" rpy="0 0 0" />
      <geometry>
        <box size="0.16 0.16 0.17" />
      </geometry>
    </collision>
    <inertial>
      <mass value="100"/>
      <inertia ixx="0.02" ixy="0.0" ixz="0.0" iyy="0.02" iyz="0.0" izz="0.005"/>
    </inertial>
  </link>

  <link name="link1">
    <visual>
      <origin xyz="0 0 -0.1" rpy="0 0 0 " />
      <geometry>
         <mesh filename="../meshes/link_1.stl" scale="1 1 1"/>
      </geometry>
      <material name="mat_silver" />
    </visual>
    <collision>
      <origin xyz="0 0.023 0.105" rpy="0 0 0" />
      <geometry>
       <box size="0.1 0.05 0.155" />
      </geometry>
    </collision>
    <inertial>
      <mass value="1"/>
      <inertia ixx="0.0004" ixy="0.0" ixz="0.0" iyy="0.0006" iyz="0.0" izz="0.00004"/>
    </inertial>
  </link>

  <link name="link2">
    <visual>
      <origin xyz="0 0 -0.22" rpy="0 0 0" />
      <geometry>
        <mesh filename="../meshes/link_2.stl" scale="1 1 1"/>
     </geometry>
     <material name="mat_silver" />
    </visual>
    <collision>
      <origin xyz="0 -0.03 0.155" rpy="0 0 0" />
      <geometry>
       <box size="0.1 0.04 0.45" />
     </geometry>
    </collision>
    <inertial>
     <mass value="1"/>
     <inertia ixx="0.00004" ixy="0.0" ixz="0.0" iyy="0.0003" iyz="0.0" izz="0.0003"/>
   </inertial>
  </link>
 <link name="link3">
    <visual>
        <origin xyz="0 0 -0.565" rpy="0 0 0" />
        <geometry>
          <mesh filename="../meshes/link_3.stl" scale="1 1 1"/>
       </geometry>
       <material name="mat_silver" />
      </visual>
    <collision>
      <origin xyz="0.01 0.036 0.115" rpy="0 0 0" />
      <geometry>
        <box size="0.12 0.04 0.32" />
      </geometry>
    </collision>
    <inertial>
      <mass value="1"/>
      <inertia ixx="0.000042" ixy="0.0" ixz="0.0" iyy="0.000042" iyz="0.0" izz="0.000042"/>
    </inertial>
  </link>
  <link name="link4">
    <visual>
        <origin xyz="0 0 -0.8" rpy="0 0 0" />
        <geometry>
          <mesh filename="../meshes/link_4.stl" scale="1 1 1"/>
       </geometry>
       <material name="mat_silver" />
      </visual>
    <collision>
      <origin xyz="0.01 -0.022 0" rpy="0 0 0" />
      <geometry>
        <box size="0.1 0.06 0.08" />
      </geometry>
    </collision>
    <inertial>
      <mass value="1"/>
      <inertia ixx="0.000042" ixy="0.0" ixz="0.0" iyy="0.000042" iyz="0.0" izz="0.000042"/>
    </inertial>
  </link>
  <link name="link5">
    <visual>
        <origin xyz="0 0 -0.85" rpy="0 0 0" />
        <geometry>
          <mesh filename="../meshes/link_5.stl" scale="1 1 1"/>
       </geometry>
       <material name="mat_silver" />
      </visual>
    <collision>
      <origin xyz="0.01 -0.02 0.1" rpy="0 0 0" />
      <geometry>
        <box size="0.2 0.06 0.12" />
      </geometry>
    </collision>
    <inertial>
      <mass value="1"/>
      <inertia ixx="0.000042" ixy="0.0" ixz="0.0" iyy="0.000042" iyz="0.0" izz="0.000042"/>
    </inertial>
  </link>

  <joint name="base_joint" type="fixed">
    <parent link="world" />
    <child link="base_link" />
    <origin xyz="0 0 0" rpy="0 0 0" />
    <dynamics damping="1.0"/>
  </joint>


  <joint name="joint1" type="continuous">
    <parent link="base_link" />
    <child link="link1" />
    <origin xyz="0 0 0.18" rpy="0 0 0" />
    <axis xyz="0 0 1" />
    <limit velocity="100" effort="100"/>
    <dynamics damping="1.0"/>
  </joint>

  <joint name="joint2" type="revolute">
    <parent link="link1" />
    <child link="link2" />
    <origin xyz="0 0 0.12" rpy="0 0 0" />
    <axis xyz="0 1 0" />
    <limit lower="-1.5707" upper="1.5707" velocity="100" effort="100" />
    <dynamics damping="1.0"/>
  </joint>

  <joint name="joint3" type="revolute">
      <parent link="link2" />
      <child link="link3" />
      <origin xyz="0 0 0.345" rpy="0 0 0" />
      <axis xyz="0 1 0" />
      <limit lower="-1.5707" upper="1.5707" velocity="100" effort="100" />
      <dynamics damping="1.0"/>
  </joint>
  <joint name="joint4" type="revolute">
    <parent link="link3" />
    <child link="link4" />
    <origin xyz="0 0 0.24" rpy="0 0 0" />
    <axis xyz="0 1 0" />
    <limit lower="-1.5707" upper="1.5707" velocity="100" effort="100" />
    <dynamics damping="1.0"/>
</joint>
<joint name="joint5" type="revolute">
    <parent link="link4" />
    <child link="link5" />
    <origin xyz="0 0 0.05" rpy="0 0 0" />
    <axis xyz="0 0 1" />
    <limit lower="-1.5707" upper="1.5707" velocity="100" effort="100" />
</joint>
</robot>
